Traceback (most recent call last):
  File "/opt/hostedtoolcache/Python/3.8.18/x64/lib/python3.8/site-packages/jupyter_cache/executors/utils.py", line 58, in single_nb_execution
    executenb(
  File "/opt/hostedtoolcache/Python/3.8.18/x64/lib/python3.8/site-packages/nbclient/client.py", line 1305, in execute
    return NotebookClient(nb=nb, resources=resources, km=km, **kwargs).execute()
  File "/opt/hostedtoolcache/Python/3.8.18/x64/lib/python3.8/site-packages/jupyter_core/utils/__init__.py", line 166, in wrapped
    return loop.run_until_complete(inner)
  File "/opt/hostedtoolcache/Python/3.8.18/x64/lib/python3.8/asyncio/base_events.py", line 616, in run_until_complete
    return future.result()
  File "/opt/hostedtoolcache/Python/3.8.18/x64/lib/python3.8/site-packages/nbclient/client.py", line 705, in async_execute
    await self.async_execute_cell(
  File "/opt/hostedtoolcache/Python/3.8.18/x64/lib/python3.8/site-packages/nbclient/client.py", line 1058, in async_execute_cell
    await self._check_raise_for_error(cell, cell_index, exec_reply)
  File "/opt/hostedtoolcache/Python/3.8.18/x64/lib/python3.8/site-packages/nbclient/client.py", line 914, in _check_raise_for_error
    raise CellExecutionError.from_cell_and_msg(cell, exec_reply_content)
nbclient.exceptions.CellExecutionError: An error occurred while executing the following cell:
------------------
import pandas as pd
import requests
from rdflib import Namespace, Graph, URIRef, Literal, BNode
from rdflib.namespace import DCTERMS, DC, XSD, RDFS, DCAT, RDF, FOAF, NamespaceManager, SKOS
import os
import urllib.parse
from datetime import datetime
import uuid
import graphviz
from ShExJSG import Schema, ShExC, ShExJ
from ShExJSG.ShExJ import Shape, IRIREF, TripleConstraint, NodeConstraint, ShapeOr, EachOf, ShapeExternal, ShapeDecl, Annotation, ObjectLiteral
from shexviz import shex2dot

symbol = dict()
symbol["class"] = "oval"
symbol["datatype"] = "octagon"
symbol["literal"] = "rectangle"
symbol["iri"]="diamond"
symbol["bnode"]='point'
symbol["oneof"]='record'

rdf = Graph()

AGSCHEMAS = Namespace("https://agschemas.org/")
AGUNITS = Namespace("https://agunits.org")
WD = Namespace("http://www.wikidata.org/entity/")
WDT = Namespace("http://www.wikidata.org/prop/direct/")
SUBJECT = Namespace("http://cottonexample.org/")
HARVESTLOCATION = Namespace("http://cottonexample.org/location/")
NALT = Namespace("https://lod.nal.usda.gov/nalt/")

OBO = Namespace("http://purl.obolibrary.org/obo/")
rdf.bind("obo", "http://purl.obolibrary.org/obo/")
SCHEMA = Namespace("https://schema.org/")
QUDT = Namespace("http://qudt.org/schema/qudt/")
UNIT = Namespace("http://qudt.org/schema/qudt/Unit/")
AGUNIT = Namespace("https://agschemas.org/units/")


rdf.bind("sio", "http://semanticscience.org/resource/")
rdf.bind("wd", "http://www.wikidata.org/entity/")
rdf.bind("wdt", "http://www.wikidata.org/prop/direct/")

def add2graphviz(command=None, arg1=None, arg2=None, shape=None, label=None):
    if command == "attr":
        localviz.attr(arg1, shape=shape)
        schema.attr(arg1, shape=shape)
    if command == "node":
        localviz.node(arg1,label=label)
        schema.node(arg1,label=label)
    if command == "edge":
        localviz.edge(arg1, arg2, label=label)
        schema.edge(arg1, arg2, label=label)
------------------


[0;31m---------------------------------------------------------------------------[0m
[0;31mModuleNotFoundError[0m                       Traceback (most recent call last)
File [0;32m/opt/hostedtoolcache/Python/3.8.18/x64/lib/python3.8/site-packages/shexviz/__init__.py:4[0m
[1;32m      3[0m [38;5;28;01mtry[39;00m:
[0;32m----> 4[0m     [38;5;28;01mimport[39;00m [38;5;21;01mtomllib[39;00m
[1;32m      5[0m [38;5;28;01mexcept[39;00m [38;5;167;01mModuleNotFoundError[39;00m:

[0;31mModuleNotFoundError[0m: No module named 'tomllib'

During handling of the above exception, another exception occurred:

[0;31mModuleNotFoundError[0m                       Traceback (most recent call last)
Cell [0;32mIn[1], line 12[0m
[1;32m     10[0m [38;5;28;01mfrom[39;00m [38;5;21;01mShExJSG[39;00m [38;5;28;01mimport[39;00m Schema, ShExC, ShExJ
[1;32m     11[0m [38;5;28;01mfrom[39;00m [38;5;21;01mShExJSG[39;00m[38;5;21;01m.[39;00m[38;5;21;01mShExJ[39;00m [38;5;28;01mimport[39;00m Shape, IRIREF, TripleConstraint, NodeConstraint, ShapeOr, EachOf, ShapeExternal, ShapeDecl, Annotation, ObjectLiteral
[0;32m---> 12[0m [38;5;28;01mfrom[39;00m [38;5;21;01mshexviz[39;00m [38;5;28;01mimport[39;00m shex2dot
[1;32m     14[0m symbol [38;5;241m=[39m [38;5;28mdict[39m()
[1;32m     15[0m symbol[[38;5;124m"[39m[38;5;124mclass[39m[38;5;124m"[39m] [38;5;241m=[39m [38;5;124m"[39m[38;5;124moval[39m[38;5;124m"[39m

File [0;32m/opt/hostedtoolcache/Python/3.8.18/x64/lib/python3.8/site-packages/shexviz/__init__.py:6[0m
[1;32m      4[0m     [38;5;28;01mimport[39;00m [38;5;21;01mtomllib[39;00m
[1;32m      5[0m [38;5;28;01mexcept[39;00m [38;5;167;01mModuleNotFoundError[39;00m:
[0;32m----> 6[0m     [38;5;28;01mimport[39;00m [38;5;21;01mtomli[39;00m [38;5;28;01mas[39;00m [38;5;21;01mtomllib[39;00m

[0;31mModuleNotFoundError[0m: No module named 'tomli'

